Traceback (most recent call last):
  File "/home/munakala/miniconda3/envs/IOOS/lib/python3.9/site-packages/jupyter_cache/executors/utils.py", line 51, in single_nb_execution
    executenb(
  File "/home/munakala/miniconda3/envs/IOOS/lib/python3.9/site-packages/nbclient/client.py", line 1112, in execute
    return NotebookClient(nb=nb, resources=resources, km=km, **kwargs).execute()
  File "/home/munakala/miniconda3/envs/IOOS/lib/python3.9/site-packages/nbclient/util.py", line 74, in wrapped
    return just_run(coro(*args, **kwargs))
  File "/home/munakala/miniconda3/envs/IOOS/lib/python3.9/site-packages/nbclient/util.py", line 53, in just_run
    return loop.run_until_complete(coro)
  File "/home/munakala/miniconda3/envs/IOOS/lib/python3.9/asyncio/base_events.py", line 642, in run_until_complete
    return future.result()
  File "/home/munakala/miniconda3/envs/IOOS/lib/python3.9/site-packages/nbclient/client.py", line 553, in async_execute
    await self.async_execute_cell(
  File "/home/munakala/miniconda3/envs/IOOS/lib/python3.9/site-packages/nbclient/client.py", line 857, in async_execute_cell
    self._check_raise_for_error(cell, exec_reply)
  File "/home/munakala/miniconda3/envs/IOOS/lib/python3.9/site-packages/nbclient/client.py", line 760, in _check_raise_for_error
    raise CellExecutionError.from_cell_and_msg(cell, exec_reply_content)
nbclient.exceptions.CellExecutionError: An error occurred while executing the following cell:
------------------
from glob import glob

import geopandas

cones, points = [], []
for fname in sorted(glob(os.path.join(base, "{}_*.zip".format(hurricane)))):
    number = os.path.splitext(os.path.split(fname)[-1])[0].split("_")[-1]
    pgn = geopandas.read_file(
        "/{}-{}_5day_pgn.shp".format(code, number), vfs="zip://{}".format(fname)
    )
    cones.append(pgn)

    pts = geopandas.read_file(
        "/{}-{}_5day_pts.shp".format(code, number), vfs="zip://{}".format(fname)
    )
    # Only the first "obsevartion."
    points.append(pts.iloc[0])
------------------

[0;31m---------------------------------------------------------------------------[0m
[0;31mCPLE_OpenFailedError[0m                      Traceback (most recent call last)
[0;32mfiona/_shim.pyx[0m in [0;36mfiona._shim.gdal_open_vector[0;34m()[0m

[0;32mfiona/_err.pyx[0m in [0;36mfiona._err.exc_wrap_pointer[0;34m()[0m

[0;31mCPLE_OpenFailedError[0m: '/vsizip//home/munakala/Documents/test-jupyterbook/test_jupyterbook/content/Code Gallery/data_analysis_and_visualization/data/al112017_5day/al112017_5day_014.zip/al112017-014_5day_pgn.shp' does not exist in the file system, and is not recognized as a supported dataset name.

During handling of the above exception, another exception occurred:

[0;31mDriverError[0m                               Traceback (most recent call last)
[0;32m<ipython-input-6-1862985ee59d>[0m in [0;36m<module>[0;34m[0m
[1;32m      6[0m [0;32mfor[0m [0mfname[0m [0;32min[0m [0msorted[0m[0;34m([0m[0mglob[0m[0;34m([0m[0mos[0m[0;34m.[0m[0mpath[0m[0;34m.[0m[0mjoin[0m[0;34m([0m[0mbase[0m[0;34m,[0m [0;34m"{}_*.zip"[0m[0;34m.[0m[0mformat[0m[0;34m([0m[0mhurricane[0m[0;34m)[0m[0;34m)[0m[0;34m)[0m[0;34m)[0m[0;34m:[0m[0;34m[0m[0;34m[0m[0m
[1;32m      7[0m     [0mnumber[0m [0;34m=[0m [0mos[0m[0;34m.[0m[0mpath[0m[0;34m.[0m[0msplitext[0m[0;34m([0m[0mos[0m[0;34m.[0m[0mpath[0m[0;34m.[0m[0msplit[0m[0;34m([0m[0mfname[0m[0;34m)[0m[0;34m[[0m[0;34m-[0m[0;36m1[0m[0;34m][0m[0;34m)[0m[0;34m[[0m[0;36m0[0m[0;34m][0m[0;34m.[0m[0msplit[0m[0;34m([0m[0;34m"_"[0m[0;34m)[0m[0;34m[[0m[0;34m-[0m[0;36m1[0m[0;34m][0m[0;34m[0m[0;34m[0m[0m
[0;32m----> 8[0;31m     pgn = geopandas.read_file(
[0m[1;32m      9[0m         [0;34m"/{}-{}_5day_pgn.shp"[0m[0;34m.[0m[0mformat[0m[0;34m([0m[0mcode[0m[0;34m,[0m [0mnumber[0m[0;34m)[0m[0;34m,[0m [0mvfs[0m[0;34m=[0m[0;34m"zip://{}"[0m[0;34m.[0m[0mformat[0m[0;34m([0m[0mfname[0m[0;34m)[0m[0;34m[0m[0;34m[0m[0m
[1;32m     10[0m     )

[0;32m~/miniconda3/envs/IOOS/lib/python3.9/site-packages/geopandas/io/file.py[0m in [0;36m_read_file[0;34m(filename, bbox, mask, rows, **kwargs)[0m
[1;32m    158[0m [0;34m[0m[0m
[1;32m    159[0m     [0;32mwith[0m [0mfiona_env[0m[0;34m([0m[0;34m)[0m[0;34m:[0m[0;34m[0m[0;34m[0m[0m
[0;32m--> 160[0;31m         [0;32mwith[0m [0mreader[0m[0;34m([0m[0mpath_or_bytes[0m[0;34m,[0m [0;34m**[0m[0mkwargs[0m[0;34m)[0m [0;32mas[0m [0mfeatures[0m[0;34m:[0m[0;34m[0m[0;34m[0m[0m
[0m[1;32m    161[0m [0;34m[0m[0m
[1;32m    162[0m             [0;31m# In a future Fiona release the crs attribute of features will[0m[0;34m[0m[0;34m[0m[0;34m[0m[0m

[0;32m~/miniconda3/envs/IOOS/lib/python3.9/site-packages/fiona/env.py[0m in [0;36mwrapper[0;34m(*args, **kwargs)[0m
[1;32m    398[0m     [0;32mdef[0m [0mwrapper[0m[0;34m([0m[0;34m*[0m[0margs[0m[0;34m,[0m [0;34m**[0m[0mkwargs[0m[0;34m)[0m[0;34m:[0m[0;34m[0m[0;34m[0m[0m
[1;32m    399[0m         [0;32mif[0m [0mlocal[0m[0;34m.[0m[0m_env[0m[0;34m:[0m[0;34m[0m[0;34m[0m[0m
[0;32m--> 400[0;31m             [0;32mreturn[0m [0mf[0m[0;34m([0m[0;34m*[0m[0margs[0m[0;34m,[0m [0;34m**[0m[0mkwargs[0m[0;34m)[0m[0;34m[0m[0;34m[0m[0m
[0m[1;32m    401[0m         [0;32melse[0m[0;34m:[0m[0;34m[0m[0;34m[0m[0m
[1;32m    402[0m             [0;32mif[0m [0misinstance[0m[0;34m([0m[0margs[0m[0;34m[[0m[0;36m0[0m[0;34m][0m[0;34m,[0m [0mstr[0m[0;34m)[0m[0;34m:[0m[0;34m[0m[0;34m[0m[0m

[0;32m~/miniconda3/envs/IOOS/lib/python3.9/site-packages/fiona/__init__.py[0m in [0;36mopen[0;34m(fp, mode, driver, schema, crs, encoding, layer, vfs, enabled_drivers, crs_wkt, **kwargs)[0m
[1;32m    254[0m [0;34m[0m[0m
[1;32m    255[0m         [0;32mif[0m [0mmode[0m [0;32min[0m [0;34m([0m[0;34m'a'[0m[0;34m,[0m [0;34m'r'[0m[0;34m)[0m[0;34m:[0m[0;34m[0m[0;34m[0m[0m
[0;32m--> 256[0;31m             c = Collection(path, mode, driver=driver, encoding=encoding,
[0m[1;32m    257[0m                            layer=layer, enabled_drivers=enabled_drivers, **kwargs)
[1;32m    258[0m         [0;32melif[0m [0mmode[0m [0;34m==[0m [0;34m'w'[0m[0;34m:[0m[0;34m[0m[0;34m[0m[0m

[0;32m~/miniconda3/envs/IOOS/lib/python3.9/site-packages/fiona/collection.py[0m in [0;36m__init__[0;34m(self, path, mode, driver, schema, crs, encoding, layer, vsi, archive, enabled_drivers, crs_wkt, ignore_fields, ignore_geometry, **kwargs)[0m
[1;32m    160[0m             [0;32mif[0m [0mself[0m[0;34m.[0m[0mmode[0m [0;34m==[0m [0;34m'r'[0m[0;34m:[0m[0;34m[0m[0;34m[0m[0m
[1;32m    161[0m                 [0mself[0m[0;34m.[0m[0msession[0m [0;34m=[0m [0mSession[0m[0;34m([0m[0;34m)[0m[0;34m[0m[0;34m[0m[0m
[0;32m--> 162[0;31m                 [0mself[0m[0;34m.[0m[0msession[0m[0;34m.[0m[0mstart[0m[0;34m([0m[0mself[0m[0;34m,[0m [0;34m**[0m[0mkwargs[0m[0;34m)[0m[0;34m[0m[0;34m[0m[0m
[0m[1;32m    163[0m             [0;32melif[0m [0mself[0m[0;34m.[0m[0mmode[0m [0;32min[0m [0;34m([0m[0;34m'a'[0m[0;34m,[0m [0;34m'w'[0m[0;34m)[0m[0;34m:[0m[0;34m[0m[0;34m[0m[0m
[1;32m    164[0m                 [0mself[0m[0;34m.[0m[0msession[0m [0;34m=[0m [0mWritingSession[0m[0;34m([0m[0;34m)[0m[0;34m[0m[0;34m[0m[0m

[0;32mfiona/ogrext.pyx[0m in [0;36mfiona.ogrext.Session.start[0;34m()[0m

[0;32mfiona/_shim.pyx[0m in [0;36mfiona._shim.gdal_open_vector[0;34m()[0m

[0;31mDriverError[0m: '/vsizip//home/munakala/Documents/test-jupyterbook/test_jupyterbook/content/Code Gallery/data_analysis_and_visualization/data/al112017_5day/al112017_5day_014.zip/al112017-014_5day_pgn.shp' does not exist in the file system, and is not recognized as a supported dataset name.
DriverError: '/vsizip//home/munakala/Documents/test-jupyterbook/test_jupyterbook/content/Code Gallery/data_analysis_and_visualization/data/al112017_5day/al112017_5day_014.zip/al112017-014_5day_pgn.shp' does not exist in the file system, and is not recognized as a supported dataset name.

