Traceback (most recent call last):
  File "/home/munakala/miniconda3/envs/IOOS/lib/python3.9/site-packages/jupyter_cache/executors/utils.py", line 51, in single_nb_execution
    executenb(
  File "/home/munakala/miniconda3/envs/IOOS/lib/python3.9/site-packages/nbclient/client.py", line 1112, in execute
    return NotebookClient(nb=nb, resources=resources, km=km, **kwargs).execute()
  File "/home/munakala/miniconda3/envs/IOOS/lib/python3.9/site-packages/nbclient/util.py", line 74, in wrapped
    return just_run(coro(*args, **kwargs))
  File "/home/munakala/miniconda3/envs/IOOS/lib/python3.9/site-packages/nbclient/util.py", line 53, in just_run
    return loop.run_until_complete(coro)
  File "/home/munakala/miniconda3/envs/IOOS/lib/python3.9/asyncio/base_events.py", line 642, in run_until_complete
    return future.result()
  File "/home/munakala/miniconda3/envs/IOOS/lib/python3.9/site-packages/nbclient/client.py", line 553, in async_execute
    await self.async_execute_cell(
  File "/home/munakala/miniconda3/envs/IOOS/lib/python3.9/site-packages/nbclient/client.py", line 857, in async_execute_cell
    self._check_raise_for_error(cell, exec_reply)
  File "/home/munakala/miniconda3/envs/IOOS/lib/python3.9/site-packages/nbclient/client.py", line 760, in _check_raise_for_error
    raise CellExecutionError.from_cell_and_msg(cell, exec_reply_content)
nbclient.exceptions.CellExecutionError: An error occurred while executing the following cell:
------------------
from IPython.display import Image

Image(m._to_png())
------------------

[0;31m---------------------------------------------------------------------------[0m
[0;31mFileNotFoundError[0m                         Traceback (most recent call last)
[0;32m~/miniconda3/envs/IOOS/lib/python3.9/site-packages/selenium/webdriver/common/service.py[0m in [0;36mstart[0;34m(self)[0m
[1;32m     71[0m             [0mcmd[0m[0;34m.[0m[0mextend[0m[0;34m([0m[0mself[0m[0;34m.[0m[0mcommand_line_args[0m[0;34m([0m[0;34m)[0m[0;34m)[0m[0;34m[0m[0;34m[0m[0m
[0;32m---> 72[0;31m             self.process = subprocess.Popen(cmd, env=self.env,
[0m[1;32m     73[0m                                             [0mclose_fds[0m[0;34m=[0m[0mplatform[0m[0;34m.[0m[0msystem[0m[0;34m([0m[0;34m)[0m [0;34m!=[0m [0;34m'Windows'[0m[0;34m,[0m[0;34m[0m[0;34m[0m[0m

[0;32m~/miniconda3/envs/IOOS/lib/python3.9/subprocess.py[0m in [0;36m__init__[0;34m(self, args, bufsize, executable, stdin, stdout, stderr, preexec_fn, close_fds, shell, cwd, env, universal_newlines, startupinfo, creationflags, restore_signals, start_new_session, pass_fds, user, group, extra_groups, encoding, errors, text, umask)[0m
[1;32m    950[0m [0;34m[0m[0m
[0;32m--> 951[0;31m             self._execute_child(args, executable, preexec_fn, close_fds,
[0m[1;32m    952[0m                                 [0mpass_fds[0m[0;34m,[0m [0mcwd[0m[0;34m,[0m [0menv[0m[0;34m,[0m[0;34m[0m[0;34m[0m[0m

[0;32m~/miniconda3/envs/IOOS/lib/python3.9/subprocess.py[0m in [0;36m_execute_child[0;34m(self, args, executable, preexec_fn, close_fds, pass_fds, cwd, env, startupinfo, creationflags, shell, p2cread, p2cwrite, c2pread, c2pwrite, errread, errwrite, restore_signals, gid, gids, uid, umask, start_new_session)[0m
[1;32m   1820[0m                         [0merr_msg[0m [0;34m=[0m [0mos[0m[0;34m.[0m[0mstrerror[0m[0;34m([0m[0merrno_num[0m[0;34m)[0m[0;34m[0m[0;34m[0m[0m
[0;32m-> 1821[0;31m                     [0;32mraise[0m [0mchild_exception_type[0m[0;34m([0m[0merrno_num[0m[0;34m,[0m [0merr_msg[0m[0;34m,[0m [0merr_filename[0m[0;34m)[0m[0;34m[0m[0;34m[0m[0m
[0m[1;32m   1822[0m                 [0;32mraise[0m [0mchild_exception_type[0m[0;34m([0m[0merr_msg[0m[0;34m)[0m[0;34m[0m[0;34m[0m[0m

[0;31mFileNotFoundError[0m: [Errno 2] No such file or directory: 'geckodriver'

During handling of the above exception, another exception occurred:

[0;31mWebDriverException[0m                        Traceback (most recent call last)
[0;32m<ipython-input-16-25167a092943>[0m in [0;36m<module>[0;34m[0m
[1;32m      1[0m [0;32mfrom[0m [0mIPython[0m[0;34m.[0m[0mdisplay[0m [0;32mimport[0m [0mImage[0m[0;34m[0m[0;34m[0m[0m
[1;32m      2[0m [0;34m[0m[0m
[0;32m----> 3[0;31m [0mImage[0m[0;34m([0m[0mm[0m[0;34m.[0m[0m_to_png[0m[0;34m([0m[0;34m)[0m[0;34m)[0m[0;34m[0m[0;34m[0m[0m
[0m
[0;32m~/miniconda3/envs/IOOS/lib/python3.9/site-packages/folium/folium.py[0m in [0;36m_to_png[0;34m(self, delay)[0m
[1;32m    317[0m             [0moptions[0m [0;34m=[0m [0mwebdriver[0m[0;34m.[0m[0mfirefox[0m[0;34m.[0m[0moptions[0m[0;34m.[0m[0mOptions[0m[0;34m([0m[0;34m)[0m[0;34m[0m[0;34m[0m[0m
[1;32m    318[0m             [0moptions[0m[0;34m.[0m[0madd_argument[0m[0;34m([0m[0;34m'--headless'[0m[0;34m)[0m[0;34m[0m[0;34m[0m[0m
[0;32m--> 319[0;31m             [0mdriver[0m [0;34m=[0m [0mwebdriver[0m[0;34m.[0m[0mFirefox[0m[0;34m([0m[0moptions[0m[0;34m=[0m[0moptions[0m[0;34m)[0m[0;34m[0m[0;34m[0m[0m
[0m[1;32m    320[0m [0;34m[0m[0m
[1;32m    321[0m             [0mhtml[0m [0;34m=[0m [0mself[0m[0;34m.[0m[0mget_root[0m[0;34m([0m[0;34m)[0m[0;34m.[0m[0mrender[0m[0;34m([0m[0;34m)[0m[0;34m[0m[0;34m[0m[0m

[0;32m~/miniconda3/envs/IOOS/lib/python3.9/site-packages/selenium/webdriver/firefox/webdriver.py[0m in [0;36m__init__[0;34m(self, firefox_profile, firefox_binary, timeout, capabilities, proxy, executable_path, options, service_log_path, firefox_options, service_args, desired_capabilities, log_path, keep_alive)[0m
[1;32m    162[0m                 [0mservice_args[0m[0;34m=[0m[0mservice_args[0m[0;34m,[0m[0;34m[0m[0;34m[0m[0m
[1;32m    163[0m                 log_path=service_log_path)
[0;32m--> 164[0;31m             [0mself[0m[0;34m.[0m[0mservice[0m[0;34m.[0m[0mstart[0m[0;34m([0m[0;34m)[0m[0;34m[0m[0;34m[0m[0m
[0m[1;32m    165[0m [0;34m[0m[0m
[1;32m    166[0m             [0mcapabilities[0m[0;34m.[0m[0mupdate[0m[0;34m([0m[0moptions[0m[0;34m.[0m[0mto_capabilities[0m[0;34m([0m[0;34m)[0m[0;34m)[0m[0;34m[0m[0;34m[0m[0m

[0;32m~/miniconda3/envs/IOOS/lib/python3.9/site-packages/selenium/webdriver/common/service.py[0m in [0;36mstart[0;34m(self)[0m
[1;32m     79[0m         [0;32mexcept[0m [0mOSError[0m [0;32mas[0m [0merr[0m[0;34m:[0m[0;34m[0m[0;34m[0m[0m
[1;32m     80[0m             [0;32mif[0m [0merr[0m[0;34m.[0m[0merrno[0m [0;34m==[0m [0merrno[0m[0;34m.[0m[0mENOENT[0m[0;34m:[0m[0;34m[0m[0;34m[0m[0m
[0;32m---> 81[0;31m                 raise WebDriverException(
[0m[1;32m     82[0m                     "'%s' executable needs to be in PATH. %s" % (
[1;32m     83[0m                         os.path.basename(self.path), self.start_error_message)

[0;31mWebDriverException[0m: Message: 'geckodriver' executable needs to be in PATH. 

WebDriverException: Message: 'geckodriver' executable needs to be in PATH. 


